<mujoco model="construction_site">
    <compiler angle="radian" coordinate="local" inertiafromgeom="true"/>
    
    <default>
        <joint armature="1" damping="1" limited="true"/>
        <geom conaffinity="1" condim="3" density="5.0" friction="1.5 0.5 0.5" margin="0.01" rgba="0.8 0.6 0.4 1"/>
        <motor ctrllimited="true" ctrlrange="-200.0 200.0"/>
    </default>
    
    <option gravity="0 0 -9.81" integrator="RK4" timestep="0.002"/>
    
    <asset>
        <texture builtin="gradient" height="100" rgb1="0.4 0.6 0.8" rgb2="0 0 0" type="skybox" width="100"/>
        <texture builtin="flat" height="128" name="texgeom" random="0.01" rgb1="0.8 0.6 0.4" rgb2="0.8 0.6 0.4" type="cube" width="127"/>
        <texture builtin="checker" height="100" name="texplane" rgb1="0.2 0.2 0.2" rgb2="0.8 0.8 0.8" type="2d" width="100"/>
        <material name="MatPlane" reflectance="0.3" shininess="1" specular="1" texrepeat="30 30" texture="texplane"/>
        <material name="geom" texture="texgeom" texuniform="true"/>
        <material name="concrete" rgba="0.7 0.7 0.7 1" shininess="0.3"/>
        <material name="steel" rgba="0.8 0.8 0.9 1" shininess="0.8" specular="0.9"/>
        <material name="wood" rgba="0.6 0.4 0.2 1" shininess="0.2"/>
        <material name="safety" rgba="1 0.5 0 1" shininess="0.5"/>
    </asset>
    
    <worldbody>
        <!-- Ground plane -->
        <geom conaffinity="1" condim="3" material="MatPlane" name="floor" pos="0 0 0" size="40 40 0.1" type="plane"/>
        
        <!-- Construction site boundaries -->
        <body name="site_boundaries">
            <!-- Safety fence around construction site -->
            <geom name="fence_north" pos="0 20 1" size="20 0.1 1" type="box" rgba="1 0.5 0 0.8"/>
            <geom name="fence_south" pos="0 -20 1" size="20 0.1 1" type="box" rgba="1 0.5 0 0.8"/>
            <geom name="fence_east" pos="20 0 1" size="0.1 20 1" type="box" rgba="1 0.5 0 0.8"/>
            <geom name="fence_west" pos="-20 0 1" size="0.1 20 1" type="box" rgba="1 0.5 0 0.8"/>
        </body>
        
        <!-- Foundation area -->
        <body name="foundation">
            <geom name="foundation_base" pos="0 0 0.05" size="10 10 0.05" type="box" material="concrete"/>
            <!-- Foundation pillars -->
            <geom name="pillar1" pos="-8 -8 0.5" size="0.5 0.5 0.5" type="box" material="concrete"/>
            <geom name="pillar2" pos="8 -8 0.5" size="0.5 0.5 0.5" type="box" material="concrete"/>
            <geom name="pillar3" pos="-8 8 0.5" size="0.5 0.5 0.5" type="box" material="concrete"/>
            <geom name="pillar4" pos="8 8 0.5" size="0.5 0.5 0.5" type="box" material="concrete"/>
        </body>
        
        <!-- Humanoid robot with enhanced construction capabilities -->
        <body name="humanoid" pos="5 0 1.5">
            <freejoint name="humanoid_root"/>
            <camera name="track" mode="trackcom" pos="0 -5 2" xyaxes="1 0 0 0 0 1"/>
            
            <!-- Torso with tool belt -->
            <geom name="torso" pos="0 0 0" size="0.35 0.25 0.3" type="capsule" rgba="0.3 0.3 0.8 1"/>
            <geom name="tool_belt" pos="0 0 -0.2" size="0.4 0.15 0.05" type="box" rgba="0.4 0.2 0.1 1"/>
            
            <!-- Head with hard hat -->
            <body name="head" pos="0 0 0.35">
                <geom name="head" pos="0 0 0.1" size="0.12 0.12 0.1" type="capsule" rgba="0.8 0.6 0.4 1"/>
                <geom name="hard_hat" pos="0 0 0.15" size="0.15 0.15 0.08" type="box" material="safety"/>
                <camera name="head_camera" pos="0.1 0 0.05" euler="0 0 0" fovy="60"/>
            </body>
            
            <!-- Arms with enhanced grippers -->
            <!-- Right arm -->
            <body name="right_upper_arm" pos="0.4 0 0.15">
                <joint name="right_shoulder1" type="hinge" axis="1 0 0" range="-2.5 2.5"/>
                <joint name="right_shoulder2" type="hinge" axis="0 1 0" range="-1.5 1.5"/>
                <joint name="right_shoulder3" type="hinge" axis="0 0 1" range="-2 2"/>
                <geom name="right_upper_arm" pos="0.2 0 0" size="0.05 0.2" type="capsule" rgba="0.3 0.3 0.8 1"/>
                
                <body name="right_lower_arm" pos="0.4 0 0">
                    <joint name="right_elbow" type="hinge" axis="0 1 0" range="-2.5 0"/>
                    <geom name="right_lower_arm" pos="0.2 0 0" size="0.04 0.2" type="capsule" rgba="0.3 0.3 0.8 1"/>
                    
                    <!-- Enhanced gripper hand -->
                    <body name="right_hand" pos="0.4 0 0">
                        <joint name="right_wrist1" type="hinge" axis="1 0 0" range="-1 1"/>
                        <joint name="right_wrist2" type="hinge" axis="0 1 0" range="-1 1"/>
                        <geom name="right_palm" pos="0 0 0" size="0.06 0.03 0.08" type="box" rgba="0.8 0.6 0.4 1"/>
                        
                        <!-- Gripper fingers -->
                        <body name="right_thumb" pos="0.06 0 0">
                            <joint name="right_thumb_joint" type="hinge" axis="0 1 0" range="0 1.5"/>
                            <geom name="right_thumb" pos="0.02 0 0" size="0.015 0.03" type="capsule" rgba="0.8 0.6 0.4 1"/>
                        </body>
                        <body name="right_finger1" pos="-0.03 0.02 0">
                            <joint name="right_finger1_joint" type="hinge" axis="0 1 0" range="0 1.5"/>
                            <geom name="right_finger1" pos="-0.02 0 0" size="0.01 0.025" type="capsule" rgba="0.8 0.6 0.4 1"/>
                        </body>
                        <body name="right_finger2" pos="-0.03 -0.02 0">
                            <joint name="right_finger2_joint" type="hinge" axis="0 1 0" range="0 1.5"/>
                            <geom name="right_finger2" pos="-0.02 0 0" size="0.01 0.025" type="capsule" rgba="0.8 0.6 0.4 1"/>
                        </body>
                    </body>
                </body>
            </body>
            
            <!-- Left arm (mirror of right) -->
            <body name="left_upper_arm" pos="-0.4 0 0.15">
                <joint name="left_shoulder1" type="hinge" axis="1 0 0" range="-2.5 2.5"/>
                <joint name="left_shoulder2" type="hinge" axis="0 1 0" range="-1.5 1.5"/>
                <joint name="left_shoulder3" type="hinge" axis="0 0 1" range="-2 2"/>
                <geom name="left_upper_arm" pos="-0.2 0 0" size="0.05 0.2" type="capsule" rgba="0.3 0.3 0.8 1"/>
                
                <body name="left_lower_arm" pos="-0.4 0 0">
                    <joint name="left_elbow" type="hinge" axis="0 1 0" range="-2.5 0"/>
                    <geom name="left_lower_arm" pos="-0.2 0 0" size="0.04 0.2" type="capsule" rgba="0.3 0.3 0.8 1"/>
                    
                    <!-- Enhanced gripper hand -->
                    <body name="left_hand" pos="-0.4 0 0">
                        <joint name="left_wrist1" type="hinge" axis="1 0 0" range="-1 1"/>
                        <joint name="left_wrist2" type="hinge" axis="0 1 0" range="-1 1"/>
                        <geom name="left_palm" pos="0 0 0" size="0.06 0.03 0.08" type="box" rgba="0.8 0.6 0.4 1"/>
                        
                        <!-- Gripper fingers -->
                        <body name="left_thumb" pos="-0.06 0 0">
                            <joint name="left_thumb_joint" type="hinge" axis="0 1 0" range="0 1.5"/>
                            <geom name="left_thumb" pos="-0.02 0 0" size="0.015 0.03" type="capsule" rgba="0.8 0.6 0.4 1"/>
                        </body>
                        <body name="left_finger1" pos="0.03 0.02 0">
                            <joint name="left_finger1_joint" type="hinge" axis="0 1 0" range="0 1.5"/>
                            <geom name="left_finger1" pos="0.02 0 0" size="0.01 0.025" type="capsule" rgba="0.8 0.6 0.4 1"/>
                        </body>
                        <body name="left_finger2" pos="0.03 -0.02 0">
                            <joint name="left_finger2_joint" type="hinge" axis="0 1 0" range="0 1.5"/>
                            <geom name="left_finger2" pos="0.02 0 0" size="0.01 0.025" type="capsule" rgba="0.8 0.6 0.4 1"/>
                        </body>
                    </body>
                </body>
            </body>
            
            <!-- Strong legs for carrying heavy materials -->
            <!-- Right leg -->
            <body name="right_thigh" pos="0.2 0 -0.4">
                <joint name="right_hip1" type="hinge" axis="1 0 0" range="-2 1"/>
                <joint name="right_hip2" type="hinge" axis="0 1 0" range="-0.5 0.5"/>
                <joint name="right_hip3" type="hinge" axis="0 0 1" range="-1 1"/>
                <geom name="right_thigh" pos="0 0 -0.25" size="0.08 0.25" type="capsule" rgba="0.3 0.3 0.8 1"/>
                
                <body name="right_shin" pos="0 0 -0.5">
                    <joint name="right_knee" type="hinge" axis="0 1 0" range="0 2.5"/>
                    <geom name="right_shin" pos="0 0 -0.2" size="0.06 0.2" type="capsule" rgba="0.3 0.3 0.8 1"/>
                    
                    <!-- Safety boot -->
                    <body name="right_foot" pos="0 0 -0.4">
                        <joint name="right_ankle1" type="hinge" axis="1 0 0" range="-1 1"/>
                        <joint name="right_ankle2" type="hinge" axis="0 1 0" range="-1 1"/>
                        <geom name="right_foot" pos="0 0.05 -0.02" size="0.08 0.15 0.03" type="box" rgba="0.2 0.2 0.2 1"/>
                        <geom name="right_boot_steel" pos="0 0.1 -0.02" size="0.08 0.05 0.04" type="box" material="steel"/>
                    </body>
                </body>
            </body>
            
            <!-- Left leg (mirror of right) -->
            <body name="left_thigh" pos="-0.2 0 -0.4">
                <joint name="left_hip1" type="hinge" axis="1 0 0" range="-2 1"/>
                <joint name="left_hip2" type="hinge" axis="0 1 0" range="-0.5 0.5"/>
                <joint name="left_hip3" type="hinge" axis="0 0 1" range="-1 1"/>
                <geom name="left_thigh" pos="0 0 -0.25" size="0.08 0.25" type="capsule" rgba="0.3 0.3 0.8 1"/>
                
                <body name="left_shin" pos="0 0 -0.5">
                    <joint name="left_knee" type="hinge" axis="0 1 0" range="0 2.5"/>
                    <geom name="left_shin" pos="0 0 -0.2" size="0.06 0.2" type="capsule" rgba="0.3 0.3 0.8 1"/>
                    
                    <!-- Safety boot -->
                    <body name="left_foot" pos="0 0 -0.4">
                        <joint name="left_ankle1" type="hinge" axis="1 0 0" range="-1 1"/>
                        <joint name="left_ankle2" type="hinge" axis="0 1 0" range="-1 1"/>
                        <geom name="left_foot" pos="0 0.05 -0.02" size="0.08 0.15 0.03" type="box" rgba="0.2 0.2 0.2 1"/>
                        <geom name="left_boot_steel" pos="0 0.1 -0.02" size="0.08 0.05 0.04" type="box" material="steel"/>
                    </body>
                </body>
            </body>
        </body>
        
        <!-- Construction crane -->
        <body name="crane_base" pos="-15 0 0">
            <geom name="crane_foundation" pos="0 0 0.5" size="2 2 0.5" type="box" material="concrete"/>
            <joint name="crane_rotation" type="hinge" axis="0 0 1" range="-3.14 3.14" damping="10"/>
            
            <!-- Crane tower -->
            <geom name="crane_tower" pos="0 0 8" size="0.5 0.5 7.5" type="box" material="steel"/>
            
            <!-- Crane arm -->
            <body name="crane_arm" pos="0 0 15">
                <joint name="crane_arm_angle" type="hinge" axis="0 1 0" range="-0.5 0.5" damping="5"/>
                <geom name="crane_arm_beam" pos="10 0 0" size="10 0.3 0.3" type="box" material="steel"/>
                
                <!-- Crane hook -->
                <body name="crane_hook" pos="20 0 0">
                    <joint name="crane_cable" type="slide" axis="0 0 1" range="-14 0" damping="2"/>
                    <geom name="crane_hook_block" pos="0 0 0" size="0.2 0.2 0.3" type="box" material="steel"/>
                    <geom name="crane_hook_tip" pos="0 0 -0.4" size="0.15 0.15 0.1" type="box" material="steel"/>
                </body>
            </body>
        </body>
        
        <!-- Construction blocks (each at top level with freejoint) -->
        <!-- Small blocks -->
        <body name="small_block1" pos="10 10 0.25">
            <freejoint/>
            <geom name="small_block1_geom" size="0.25 0.25 0.125" type="box" material="concrete" mass="10"/>
        </body>
        <body name="small_block2" pos="10.6 10 0.25">
            <freejoint/>
            <geom name="small_block2_geom" size="0.25 0.25 0.125" type="box" material="concrete" mass="10"/>
        </body>
        <body name="small_block3" pos="11.2 10 0.25">
            <freejoint/>
            <geom name="small_block3_geom" size="0.25 0.25 0.125" type="box" material="concrete" mass="10"/>
        </body>
        
        <!-- Medium blocks -->
        <body name="medium_block1" pos="10 11 0.25">
            <freejoint/>
            <geom name="medium_block1_geom" size="0.5 0.25 0.125" type="box" material="concrete" mass="20"/>
        </body>
        <body name="medium_block2" pos="11.2 11 0.25">
            <freejoint/>
            <geom name="medium_block2_geom" size="0.5 0.25 0.125" type="box" material="concrete" mass="20"/>
        </body>
        
        <!-- Large blocks -->
        <body name="large_block1" pos="10 12 0.5">
            <freejoint/>
            <geom name="large_block1_geom" size="1 0.5 0.25" type="box" material="concrete" mass="40"/>
        </body>
        
        <!-- Material storage area -->
        <body name="material_storage" pos="15 -10 0">
            <geom name="storage_platform" pos="0 0 0.1" size="5 5 0.1" type="box" rgba="0.5 0.5 0.5 1"/>
        </body>
        
        <!-- Steel beams (at top level) -->
        <body name="steel_beam1" pos="13 -10 0.3">
            <freejoint/>
            <geom name="steel_beam1_geom" size="0.15 0.15 2" type="box" material="steel" mass="50"/>
        </body>
        <body name="steel_beam2" pos="14 -10 0.3">
            <freejoint/>
            <geom name="steel_beam2_geom" size="0.15 0.15 2" type="box" material="steel" mass="50"/>
        </body>
        
        <!-- Wood planks (at top level) -->
        <body name="wood_plank1" pos="16 -10 0.2">
            <freejoint/>
            <geom name="wood_plank1_geom" size="1 0.2 0.05" type="box" material="wood" mass="5"/>
        </body>
        <body name="wood_plank2" pos="16 -9.5 0.2">
            <freejoint/>
            <geom name="wood_plank2_geom" size="1 0.2 0.05" type="box" material="wood" mass="5"/>
        </body>
        
        <!-- Safety equipment station -->
        <body name="safety_station" pos="-10 -15 0">
            <geom name="safety_station_base" pos="0 0 0.5" size="1 1 0.5" type="box" material="safety"/>
            <geom name="safety_sign" pos="0 0 2" size="0.5 0.05 0.5" type="box" rgba="1 1 0 1"/>
        </body>
        
        <!-- Construction target area markers -->
        <body name="target_markers">
            <geom name="target1" pos="0 5 0.01" size="1 1 0.01" type="box" rgba="0 1 0 0.3" contype="0" conaffinity="0"/>
            <geom name="target2" pos="0 7 0.01" size="1 1 0.01" type="box" rgba="0 1 0 0.3" contype="0" conaffinity="0"/>
            <geom name="target3" pos="0 9 0.01" size="1 1 0.01" type="box" rgba="0 1 0 0.3" contype="0" conaffinity="0"/>
        </body>
        
        <!-- Lighting for construction site -->
        <light cutoff="100" diffuse="1 1 1" dir="0 0 -1" directional="true" exponent="1" pos="0 0 30" specular="0.5 0.5 0.5"/>
        <light cutoff="50" diffuse="0.8 0.8 0.8" dir="1 0 -0.5" directional="true" pos="-20 0 20" specular="0.3 0.3 0.3"/>
        <light cutoff="50" diffuse="0.8 0.8 0.8" dir="-1 0 -0.5" directional="true" pos="20 0 20" specular="0.3 0.3 0.3"/>
    </worldbody>
    
    <actuator>
        <!-- Humanoid actuators with construction-appropriate strength -->
        <!-- Arms -->
        <motor name="right_shoulder1_motor" joint="right_shoulder1" gear="100"/>
        <motor name="right_shoulder2_motor" joint="right_shoulder2" gear="100"/>
        <motor name="right_shoulder3_motor" joint="right_shoulder3" gear="100"/>
        <motor name="right_elbow_motor" joint="right_elbow" gear="80"/>
        <motor name="right_wrist1_motor" joint="right_wrist1" gear="50"/>
        <motor name="right_wrist2_motor" joint="right_wrist2" gear="50"/>
        <motor name="right_thumb_motor" joint="right_thumb_joint" gear="30"/>
        <motor name="right_finger1_motor" joint="right_finger1_joint" gear="30"/>
        <motor name="right_finger2_motor" joint="right_finger2_joint" gear="30"/>
        
        <motor name="left_shoulder1_motor" joint="left_shoulder1" gear="100"/>
        <motor name="left_shoulder2_motor" joint="left_shoulder2" gear="100"/>
        <motor name="left_shoulder3_motor" joint="left_shoulder3" gear="100"/>
        <motor name="left_elbow_motor" joint="left_elbow" gear="80"/>
        <motor name="left_wrist1_motor" joint="left_wrist1" gear="50"/>
        <motor name="left_wrist2_motor" joint="left_wrist2" gear="50"/>
        <motor name="left_thumb_motor" joint="left_thumb_joint" gear="30"/>
        <motor name="left_finger1_motor" joint="left_finger1_joint" gear="30"/>
        <motor name="left_finger2_motor" joint="left_finger2_joint" gear="30"/>
        
        <!-- Legs -->
        <motor name="right_hip1_motor" joint="right_hip1" gear="150"/>
        <motor name="right_hip2_motor" joint="right_hip2" gear="150"/>
        <motor name="right_hip3_motor" joint="right_hip3" gear="150"/>
        <motor name="right_knee_motor" joint="right_knee" gear="120"/>
        <motor name="right_ankle1_motor" joint="right_ankle1" gear="80"/>
        <motor name="right_ankle2_motor" joint="right_ankle2" gear="80"/>
        
        <motor name="left_hip1_motor" joint="left_hip1" gear="150"/>
        <motor name="left_hip2_motor" joint="left_hip2" gear="150"/>
        <motor name="left_hip3_motor" joint="left_hip3" gear="150"/>
        <motor name="left_knee_motor" joint="left_knee" gear="120"/>
        <motor name="left_ankle1_motor" joint="left_ankle1" gear="80"/>
        <motor name="left_ankle2_motor" joint="left_ankle2" gear="80"/>
        
        <!-- Crane controls -->
        <motor name="crane_rotation_motor" joint="crane_rotation" gear="500"/>
        <motor name="crane_arm_motor" joint="crane_arm_angle" gear="300"/>
        <motor name="crane_cable_motor" joint="crane_cable" gear="200"/>
    </actuator>
</mujoco>